<?xml version="1.0" encoding="utf-8"?>
<!-- This URDF was automatically created by SolidWorks to URDF Exporter! Originally created by Stephen Brawner (brawner@gmail.com) 
     Commit Version: 1.6.0-4-g7f85cfe  Build Version: 1.6.7995.38578
     For more information, please see http://wiki.ros.org/sw_urdf_exporter -->
<robot
  name="rbot">
  <link
    name="base_link">
    <inertial>
      <origin
        xyz="-0.012172 0.00015707 -0.048435"
        rpy="0 0 0" />
      <mass
        value="5.4228" />
      <inertia
        ixx="0.0083305"
        ixy="-1.3518E-07"
        ixz="0.00024797"
        iyy="0.0087755"
        iyz="-8.3209E-07"
        izz="0.016381" />
    </inertial>
    <visual>
      <origin
        xyz="0 0 0"
        rpy="0 0 0" />
      <geometry>
        <mesh
          filename="package://rbot/meshes/base_link.STL" />
      </geometry>
      <material
        name="">
        <color
          rgba="0 0 0 0" />
      </material>
    </visual>
    <collision>
      <origin
        xyz="0 0 0"
        rpy="0 0 0" />
      <geometry>
        <mesh
          filename="package://rbot/meshes/base_link.STL" />
      </geometry>
    </collision>
  </link>
  <link
    name="fWheel">
    <inertial>
      <origin
        xyz="1.6653E-15 0.004 4.996E-16"
        rpy="0 0 0" />
      <mass
        value="0.34828" />
      <inertia
        ixx="1.4979E-06"
        ixy="6.8554E-39"
        ixz="-6.3017E-39"
        iyy="2.6586E-06"
        iyz="4.4557E-21"
        izz="1.4979E-06" />
    </inertial>
    <visual>
      <origin
        xyz="0 0 0"
        rpy="0 0 0" />
      <geometry>
        <mesh
          filename="package://rbot/meshes/fWheel.STL" />
      </geometry>
      <material
        name="">
        <color
          rgba="0.79216 0.81961 0.93333 1" />
      </material>
    </visual>
    <collision>
      <origin
        xyz="0 0 0"
        rpy="0 0 0" />
      <geometry>
        <mesh
          filename="package://rbot/meshes/fWheel.STL" />
      </geometry>
    </collision>
  </link>
  <joint
    name="fWheel_bc"
    type="continuous">
    <origin
      xyz="0.10498 -0.004012 -0.09452"
      rpy="0 0 0" />
    <parent
      link="base_link" />
    <child
      link="fWheel" />
    <axis
      xyz="0 -1 0" />
          <joint_properties damping="0.1" friction="1.0"/>
                <limit effort="2.6" velocity="20"/>
  </joint>
  <link
    name="l_rWheel">
    <inertial>
      <origin
        xyz="3.3862E-15 0.010693 1.6653E-15"
        rpy="0 0 0" />
      <mass
        value="0.52108" />
      <inertia
        ixx="8.5294E-05"
        ixy="-2.2354E-20"
        ixz="-1.1654E-19"
        iyy="1.5938E-04"
        iyz="5.156E-19"
        izz="8.5294E-05" />
    </inertial>
    <visual>
      <origin
        xyz="0 0 0"
        rpy="0 0 0" />
      <geometry>
        <mesh
          filename="package://rbot/meshes/l_rWheel.STL" />
      </geometry>
      <material
        name="">
        <color
          rgba="0.75294 0.75294 0.75294 1" />
      </material>
    </visual>
    <collision>
      <origin
        xyz="0 0 0"
        rpy="0 0 0" />
      <geometry>
        <mesh
          filename="package://rbot/meshes/l_rWheel.STL" />
      </geometry>
    </collision>
  </link>
  <joint
    name="l_rWheel_bc"
    type="continuous">
    <origin
      xyz="-0.047024 0.074988 -0.08"
      rpy="0 0 0" />
    <parent
      link="base_link" />
    <child
      link="l_rWheel" />
    <axis
      xyz="0 1 0" />
          <joint_properties damping="0.1" friction="1.0"/>
                <limit effort="2.6" velocity="20"/>
  </joint>
  <link
    name="r_rWheel">
    <inertial>
      <origin
        xyz="-1.6653E-16 0.0083074 0"
        rpy="0 0 0" />
      <mass
        value="0.52108" />
      <inertia
        ixx="8.5294E-05"
        ixy="-1.5452E-18"
        ixz="1.7644E-20"
        iyy="1.5938E-04"
        iyz="4.8937E-20"
        izz="8.5294E-05" />
    </inertial>
    <visual>
      <origin
        xyz="0 0 0"
        rpy="0 0 0" />
      <geometry>
        <mesh
          filename="package://rbot/meshes/r_rWheel.STL" />
      </geometry>
      <material
        name="">
        <color
          rgba="0.75294 0.75294 0.75294 1" />
      </material>
    </visual>
    <collision>
      <origin
        xyz="0 0 0"
        rpy="0 0 0" />
      <geometry>
        <mesh
          filename="package://rbot/meshes/r_rWheel.STL" />
      </geometry>
    </collision>
  </link>
  <joint
    name="r_rWheel_bc"
    type="continuous">
    <origin
      xyz="-0.047024 -0.094012 -0.08"
      rpy="0 0 0" />
    <parent
      link="base_link" />
    <child
      link="r_rWheel" />
    <axis
      xyz="0 1 0" />
          <joint_properties damping="0.1" friction="1.0"/>
                <limit effort="2.6" velocity="20"/>
  </joint>
  <link
    name="fan">
    <inertial>
      <origin
        xyz="-1.1102E-16 -2.7756E-17 0.0077206"
        rpy="0 0 0" />
      <mass
        value="0.025691" />
      <inertia
        ixx="8.875E-07"
        ixy="-5.0086E-23"
        ixz="-2.4209E-21"
        iyy="8.875E-07"
        iyz="1.8061E-22"
        izz="1.6294E-06" />
    </inertial>
    <visual>
      <origin
        xyz="0 0 0"
        rpy="0 0 0" />
      <geometry>
        <mesh
          filename="package://rbot/meshes/fan.STL" />
      </geometry>
      <material
        name="">
        <color
          rgba="0.79216 0.81961 0.93333 1" />
      </material>
    </visual>
    <collision>
      <origin
        xyz="0 0 0"
        rpy="0 0 0" />
      <geometry>
        <mesh
          filename="package://rbot/meshes/fan.STL" />
      </geometry>
    </collision>
  </link>
  <joint
    name="fan_bc"
    type="continuous">
    <origin
      xyz="0.009976 -1.1899E-05 -0.069083"
      rpy="0 0 0" />
    <parent
      link="base_link" />
    <child
      link="fan" />
    <axis
      xyz="0 0 -1" />
  </joint>
  <link
    name="Camera_base">
    <inertial>
      <origin
        xyz="5.9319E-05 -0.017419 0.063064"
        rpy="0 0 0" />
      <mass
        value="0.20962" />
      <inertia
        ixx="0.00017945"
        ixy="-2.6127E-09"
        ixz="9.9494E-10"
        iyy="6.7581E-05"
        iyz="-1.1353E-05"
        izz="0.0001248" />
    </inertial>
    <visual>
      <origin
        xyz="0 0 0"
        rpy="0 0 0" />
      <geometry>
        <mesh
          filename="package://rbot/meshes/Camera_base.STL" />
      </geometry>
      <material
        name="">
        <color
          rgba="0.75294 0.75294 0.75294 1" />
      </material>
    </visual>
    <collision>
      <origin
        xyz="0 0 0"
        rpy="0 0 0" />
      <geometry>
        <mesh
          filename="package://rbot/meshes/Camera_base.STL" />
      </geometry>
    </collision>
  </link>
  <joint
    name="Camera_base_tc"
    type="fixed">
     <origin
      xyz="-0.0750239674809218 -1.19645664770351E-05 0.00499999999999973"
      rpy="0 0 0" />
    <parent
      link="base_link" />
    <child
      link="Camera_base" />
    <axis
      xyz="0 0 0" />
  </joint>
  <link
    name="Camera">
    <inertial>
      <origin
        xyz="-0.00027597 -0.062357 2.6907E-06"
        rpy="0 0 0" />
      <mass
        value="0.16364" />
      <inertia
        ixx="6.9627E-05"
        ixy="5.9527E-19"
        ixz="1.0089E-06"
        iyy="1.1797E-05"
        iyz="2.5215E-20"
        izz="6.6738E-05" />
    </inertial>
    <visual>
      <origin
        xyz="0 0 0"
        rpy="0 0 0" />
      <geometry>
        <mesh
          filename="package://rbot/meshes/Camera.STL" />
      </geometry>
      <material
        name="">
        <color
          rgba="0.75294 0.75294 0.75294 1" />
      </material>
    </visual>
    <collision>
      <origin
        xyz="0 0 0"
        rpy="0 0 0" />
      <geometry>
        <mesh
          filename="package://rbot/meshes/Camera.STL" />
      </geometry>
    </collision>
  </link>
  <joint
    name="Camera_Camera_base"
    type="continuous">
    <origin
      xyz="0.000199999999997202 0.0644000000000001 0.0900000000000034"
      rpy="0 0 0" />
              <joint_properties damping="0.1" friction="1.0"/>
                <limit effort="2.6" velocity="20"/>
    <parent
      link="Camera_base" />
    <child
      link="Camera" />
    <axis
      xyz="0 1 0" />

  </joint>
  <link
    name="LiDar">
    <inertial>
      <origin
        xyz="0 0 0"
        rpy="0 0 0" />
      <mass
        value="0.2" />
      <inertia
        ixx="0"
        ixy="0"
        ixz="0"
        iyy="0"
        iyz="0"
        izz="0" />
    </inertial>
    <visual>
      <origin
        xyz="0 0 0"
        rpy="0 0 0" />
      <geometry>
        <mesh
          filename="package://rbot/meshes/LiDar.STL" />
      </geometry>
      <material
        name="">
        <color
          rgba="1 1 1 1" />
      </material>
    </visual>
    <collision>
      <origin
        xyz="0 0 0"
        rpy="0 0 0" />
      <geometry>
        <mesh
          filename="package://rbot/meshes/LiDar.STL" />
      </geometry>
    </collision>
  </link>
  <joint
    name="LiDar_tc"
    type="fixed">
    <origin
      xyz="-2.3967480921927E-05 -1.19645664762025E-05 0.019"
      rpy="0 0 0" />
    <parent
      link="base_link" />
    <child
      link="LiDar" />
    <axis
      xyz="0 0 0" />
  </joint>
    <gazebo>
    <plugin name="gazebo_ros_control" filename="libgazebo_ros_control.so">
    <robotNamespace>rbot</robotNamespace>
    </plugin>
</gazebo>  
<transmission name="tran1">
    <type>transmission_interface/SimpleTransmission</type>
    <joint name="Camera_Camera_base">
        <hardwareInterface>EffortJointInterface</hardwareInterface>
    </joint>
    <actuator name="camera_motor">
        <hardwareInterface>EffortJointInterface</hardwareInterface>
        <mechanicalReduction>1</mechanicalReduction>
    </actuator>
</transmission>
<transmission name="tran2">
    <type>transmission_interface/SimpleTransmission</type>
    <joint name="r_rWheel_bc">
        <hardwareInterface>EffortJointInterface</hardwareInterface>
    </joint>
    <actuator name="r_rWheel_bc_motor">
        <hardwareInterface>EffortJointInterface</hardwareInterface>
        <mechanicalReduction>50</mechanicalReduction>
    </actuator>
</transmission>
<transmission name="tran3">
    <type>transmission_interface/SimpleTransmission</type>
    <joint name="l_rWheel_bc">
        <hardwareInterface>EffortJointInterface</hardwareInterface>
    </joint>
    <actuator name="l_rWheel_bc_motor">
        <hardwareInterface>EffortJointInterface</hardwareInterface>
        <mechanicalReduction>50</mechanicalReduction>
    </actuator>
</transmission>

  <gazebo reference="Camera">
    <sensor type="camera" name="camera1">
      <update_rate>30.0</update_rate>
      <camera name="head">
        <horizontal_fov>1.3962634</horizontal_fov>
        <image>
          <width>800</width>
          <height>800</height>
          <format>R8G8B8</format>
        </image>
        <clip>
          <near>0.02</near>
          <far>300</far>
        </clip>
        <noise>
          <type>gaussian</type>
          <!-- Noise is sampled independently per pixel on each frame.
               That pixel's noise value is added to each of its color
               channels, which at that point lie in the range [0,1]. -->
          <mean>0.0</mean>
          <stddev>0.007</stddev>
        </noise>
      </camera>
      <plugin name="camera_controller" filename="libgazebo_ros_camera.so">
        <alwaysOn>true</alwaysOn>
        <updateRate>0.0</updateRate>
        <cameraName>gazebo_demo/camera</cameraName>
        <imageTopicName>image_raw</imageTopicName>
        <cameraInfoTopicName>camera_info</cameraInfoTopicName>
        <frameName>Camera</frameName>
        <hackBaseline>0.07</hackBaseline>
        <distortionK1>0.0</distortionK1>
        <distortionK2>0.0</distortionK2>
        <distortionK3>0.0</distortionK3>
        <distortionT1>0.0</distortionT1>
        <distortionT2>0.0</distortionT2>
      </plugin>
    </sensor>
  </gazebo>
  <!-- hokuyo -->
  <gazebo reference="LiDar">
    <sensor type="gpu_ray" name="head_hokuyo_sensor">
      <pose>0 0 0 0 0 3.14</pose>
      <visualize>false</visualize>
      <update_rate>100</update_rate>
      <ray>
        <scan>
          <horizontal>
            <samples>720</samples>
            <resolution>1</resolution>
            <min_angle>-3.14</min_angle>
            <max_angle>3.14</max_angle>
          </horizontal>
        </scan>
        <range>
          <min>0.10</min>
          <max>30.0</max>
          <resolution>0.01</resolution>
        </range>
        <noise>
          <type>gaussian</type>
          <!-- Noise parameters based on published spec for Hokuyo laser
               achieving "+-30mm" accuracy at range < 10m.  A mean of 0.0m and
               stddev of 0.01m will put 99.7% of samples within 0.03m of the true
               reading. -->
          <mean>0.0</mean>
          <stddev>0.01</stddev>
        </noise>
      </ray>
      <plugin name="gazebo_ros_head_hokuyo_controller" filename="libgazebo_ros_gpu_laser.so">
        <topicName>/scan</topicName>
        <frameName>LiDar</frameName>
      </plugin>
    </sensor>
  </gazebo>
  <gazebo>
  <plugin name="differential_drive_controller" filename="libgazebo_ros_diff_drive.so">

    <!-- Plugin update rate in Hz -->
    <updateRate>100</updateRate>

    <!-- Name of left joint, defaults to `left_joint` -->
    <leftJoint>l_rWheel_bc</leftJoint>

    <!-- Name of right joint, defaults to `right_joint` -->
    <rightJoint>r_rWheel_bc</rightJoint>

    <!-- The distance from the center of one wheel to the other, in meters, defaults to 0.34 m -->
    <wheelSeparation>0.169</wheelSeparation>

    <!-- Diameter of the wheels, in meters, defaults to 0.15 m -->
    <wheelDiameter>0.064</wheelDiameter>

    <!-- Wheel acceleration, in rad/s^2, defaults to 0.0 rad/s^2 -->
    <wheelAcceleration>0.5</wheelAcceleration>

    <!-- Maximum torque which the wheels can produce, in Nm, defaults to 5 Nm -->
    <wheelTorque>10</wheelTorque>

    <!-- Topic to receive geometry_msgs/Twist message commands, defaults to `cmd_vel` -->
    <commandTopic>cmd_vel</commandTopic>

    <!-- Topic to publish nav_msgs/Odometry messages, defaults to `odom` -->
    <odometryTopic>odom</odometryTopic>

    <!-- Odometry frame, defaults to `odom` -->
    <odometryFrame>odom</odometryFrame>

    <!-- Robot frame to calculate odometry from, defaults to `base_footprint` -->
    <robotBaseFrame>base_link</robotBaseFrame>

    <!-- Odometry source, 0 for ENCODER, 1 for WORLD, defaults to WORLD -->
    <odometrySource>1</odometrySource>

    <!-- Set to true to publish transforms for the wheel links, defaults to false -->
    <publishWheelTF>true</publishWheelTF>

    <!-- Set to true to publish transforms for the odometry, defaults to true -->
    <publishOdom>true</publishOdom>

    <!-- Set to true to publish sensor_msgs/JointState on /joint_states for the wheel joints, defaults to false -->
    <publishWheelJointState>true</publishWheelJointState>

    <!-- Set to true to swap right and left wheels, defaults to true -->
    <legacyMode>false</legacyMode>
  </plugin>
</gazebo>
  <joint name="imu_joint" type="fixed">
      <axis xyz="0 0 1" />
      <origin xyz="0 0 0.015" rpy="0 0 0"/>
      <parent link="base_link"/>
      <child link="imu_link"/>
  </joint>
  <!-- Imu Link-->
  <link name="imu_link">
        <collision>
            <origin xyz="0 0 0" rpy="0 0 0"/>
            <geometry>
                <box size="0.01 0.01 0.01"/>
            </geometry>
        </collision>
        <visual>
            <origin xyz="0 0 0" rpy="0 0 0"/>
            <geometry>
                <box size="0.01 0.01 0.01"/>
            </geometry>
        </visual>
        <inertial>
            <mass value="0.001" />
            <origin xyz="0 0 0" rpy="0 0 0"/>
            <inertia ixx="0.00000015" ixy="0" ixz="0" iyy="0.00000015" iyz="0" izz="0.00000015" />
        </inertial>
  </link>
  <!--IMU Link gazebo plugin-->
  <gazebo reference="imu_link">
    <gravity>true</gravity>
    <sensor name="imu_sensor" type="imu">
      <always_on>true</always_on>
      <update_rate>100</update_rate>
      <visualize>true</visualize>
      <topic>__default_topic__</topic>
      <plugin filename="libgazebo_ros_imu_sensor.so" name="imu_plugin">
        <topicName>/imu</topicName>
        <bodyName>imu_link</bodyName>
        <updateRateHZ>100.0</updateRateHZ>
        <gaussianNoise>0.0</gaussianNoise>
        <xyzOffset>0 0 0</xyzOffset>
        <rpyOffset>0 0 0</rpyOffset>
        <frameName>imu_link</frameName>
        <initialOrientationAsReference>false</initialOrientationAsReference>
      </plugin>
      <pose>0 0 0 0 0 0</pose>
    </sensor>
  </gazebo>
  <gazebo reference="base_link">
      <selfCollide>false</selfCollide>

    <material>Gazebo/RedBright</material>
  </gazebo> 
  <gazebo reference="Camera_base">
      <selfCollide>false</selfCollide>

    <material>Gazebo/DarkGrey</material>
  </gazebo> 
  <gazebo reference="Camera">
      <selfCollide>false</selfCollide>

    <material>Gazebo/Grey</material>
  </gazebo> 
  <gazebo reference="LiDar">
      <selfCollide>false</selfCollide>

    <material>Gazebo/White</material>
  </gazebo> 
    <gazebo reference="fWheel">
        <mu1>0</mu1>
    <mu2>0</mu2>
    <material>Gazebo/Black</material>
        <selfCollide>false</selfCollide>

  </gazebo> 
    <gazebo reference="r_rWheel">
        <mu1>1000000</mu1>
    <mu2>1000000</mu2>
      <kp>10000000.0</kp>
  <kd>1000.0</kd>
    <material>Gazebo/Black</material>
        <selfCollide>false</selfCollide>

  </gazebo> 
    <gazebo reference="l_rWheel">
        <mu1>1000000</mu1>
    <mu2>1000000</mu2>
      <kp>10000000.0</kp>
  <kd>1000.0</kd>
    <material>Gazebo/Black</material>
        <selfCollide>false</selfCollide>

  </gazebo> 


</robot>